<?xml version="1.0" encoding="utf-8"?>
<!DOCTYPE TS>
<TS version="2.1" language="ja_JP" sourcelanguage="en_US">
<context>
    <name>AreaDataGenerator</name>
    <message>
        <location filename="../algorithms/utils/area_data_generator.py" line="111"/>
        <source>railway_stations</source>
        <translation>鉄道駅</translation>
    </message>
    <message>
        <location filename="../algorithms/utils/area_data_generator.py" line="203"/>
        <source>The %1 layer is invalid.</source>
        <translation>%1 レイヤが無効です。</translation>
    </message>
    <message>
        <location filename="../algorithms/utils/area_data_generator.py" line="2349"/>
        <source>Failed to add layer to GeoPackage.</source>
        <translation>GeoPackage にレイヤを追加できませんでした。</translation>
    </message>
    <message>
        <location filename="../algorithms/utils/area_data_generator.py" line="174"/>
        <source>railway station buffer</source>
        <translation>鉄道駅カバー圏域</translation>
    </message>
    <message>
        <location filename="../algorithms/utils/area_data_generator.py" line="2352"/>
        <source>%1 data generation completed.</source>
        <translation>%1 データの生成が完了しました。</translation>
    </message>
    <message>
        <location filename="../algorithms/utils/area_data_generator.py" line="2467"/>
        <source>Plugin</source>
        <translation>プラグイン</translation>
    </message>
    <message>
        <location filename="../algorithms/utils/area_data_generator.py" line="2363"/>
        <source>An error occurred: %1</source>
        <translation>エラーが発生しました: %1</translation>
    </message>
    <message>
        <location filename="../algorithms/utils/area_data_generator.py" line="202"/>
        <source>bus_stops</source>
        <translation>バス停</translation>
    </message>
    <message>
        <location filename="../algorithms/utils/area_data_generator.py" line="264"/>
        <source>bus stop buffer</source>
        <translation>バス停カバー圏域</translation>
    </message>
    <message>
        <location filename="../algorithms/utils/area_data_generator.py" line="2228"/>
        <source>Failed to load layer: %1</source>
        <translation>レイヤの読み込みに失敗しました: %1</translation>
    </message>
    <message>
        <location filename="../algorithms/utils/area_data_generator.py" line="2061"/>
        <source>shelter</source>
        <translation>避難施設</translation>
    </message>
    <message>
        <location filename="../algorithms/utils/area_data_generator.py" line="2246"/>
        <source>%1 cannot be loaded as %2 data.</source>
        <translation>%1 を %2 データとして読み込めません。</translation>
    </message>
    <message>
        <location filename="../algorithms/utils/area_data_generator.py" line="2292"/>
        <source>No valid %1 Shapefile was found.</source>
        <translation>有効な %1 Shapefile が見つかりませんでした。</translation>
    </message>
    <message>
        <location filename="../algorithms/utils/area_data_generator.py" line="451"/>
        <source>The %1 layer was not found.</source>
        <translation>%1 レイヤが見つかりませんでした。</translation>
    </message>
    <message>
        <location filename="../algorithms/utils/area_data_generator.py" line="529"/>
        <source>Shelter geometry is not a Point: %1</source>
        <translation>避難施設ジオメトリがポイントではありません: %1</translation>
    </message>
    <message>
        <location filename="../algorithms/utils/area_data_generator.py" line="577"/>
        <source>AreaDataGenerator: Buffered object is not a polygon.</source>
        <translation>AreaDataGenerator: バッファリングされたオブジェクトがポリゴンではありません。</translation>
    </message>
    <message>
        <location filename="../algorithms/utils/area_data_generator.py" line="592"/>
        <source>shelter buffer</source>
        <translation>避難施設カバー圏域</translation>
    </message>
    <message>
        <location filename="../algorithms/utils/area_data_generator.py" line="628"/>
        <source>Empty geometry for road feature.</source>
        <translation>道路フィーチャのジオメトリが空です。</translation>
    </message>
    <message>
        <location filename="../algorithms/utils/area_data_generator.py" line="680"/>
        <source>Unsupported geometry type: %1</source>
        <translation>サポートされていないジオメトリタイプです: %1</translation>
    </message>
    <message>
        <location filename="../algorithms/utils/area_data_generator.py" line="1174"/>
        <source>induction area</source>
        <translation>誘導区域</translation>
    </message>
    <message>
        <location filename="../algorithms/utils/area_data_generator.py" line="852"/>
        <source>No Shapefile found for the %1.</source>
        <translation>%1 の Shapefile が見つかりません。</translation>
    </message>
    <message>
        <location filename="../algorithms/utils/area_data_generator.py" line="1066"/>
        <source>urbun planning</source>
        <translation>都市計画区域</translation>
    </message>
    <message>
        <location filename="../algorithms/utils/area_data_generator.py" line="1147"/>
        <source>urbun_planning</source>
        <translation>都市計画区域</translation>
    </message>
    <message>
        <location filename="../algorithms/utils/area_data_generator.py" line="1313"/>
        <source>land use area</source>
        <translation>土地利用区域</translation>
    </message>
    <message>
        <location filename="../algorithms/utils/area_data_generator.py" line="1419"/>
        <source>hazard area planned scales</source>
        <translation>ハザード区域計画規模</translation>
    </message>
    <message>
        <location filename="../algorithms/utils/area_data_generator.py" line="1479"/>
        <source>hazard area planned scale</source>
        <translation>ハザード区域計画規模</translation>
    </message>
    <message>
        <location filename="../algorithms/utils/area_data_generator.py" line="1645"/>
        <source>hazard area maximum scale</source>
        <translation>ハザード区域最大規模</translation>
    </message>
    <message>
        <location filename="../algorithms/utils/area_data_generator.py" line="1823"/>
        <source>hazard area storm surge</source>
        <translation>高潮浸水区域</translation>
    </message>
    <message>
        <location filename="../algorithms/utils/area_data_generator.py" line="1995"/>
        <source>hazard area tsunami</source>
        <translation>津波浸水区域</translation>
    </message>
    <message>
        <location filename="../algorithms/utils/area_data_generator.py" line="2185"/>
        <source>hazard area landslide</source>
        <translation>土砂災害区域</translation>
    </message>
    <message>
        <location filename="../algorithms/utils/area_data_generator.py" line="2351"/>
        <source>hazard area floodplain</source>
        <translation>洪水浸水区域</translation>
    </message>
    <message>
        <location filename="../algorithms/utils/area_data_generator.py" line="2385"/>
        <source>Directory: %1</source>
        <translation>ディレクトリ: %1</translation>
    </message>
    <message>
        <location filename="../algorithms/utils/area_data_generator.py" line="2421"/>
        <source>%1 was detected. Using SHIFT_JIS for the file %2.</source>
        <translation>%1 が検出されました。ファイル %2 に SHIFT_JIS を使用します。</translation>
    </message>
    <message>
        <location filename="../algorithms/utils/area_data_generator.py" line="2431"/>
        <source>Encoding: %1</source>
        <translation>エンコーディング: %1</translation>
    </message>
    <message>
        <location filename="../algorithms/utils/area_data_generator.py" line="2439"/>
        <source>No corresponding DBF file was found for the specified path: %1.</source>
        <translation>指定されたパス %1 に対応する DBF ファイルが見つかりませんでした。</translation>
    </message>
    <message>
        <location filename="../algorithms/utils/area_data_generator.py" line="2452"/>
        <source>Fixing invalid geometries in layer: %1.</source>
        <translation>レイヤ %1 の無効なジオメトリを修正中。</translation>
    </message>
    <message>
        <location filename="../algorithms/utils/area_data_generator.py" line="2464"/>
        <source>Completed fixing invalid geometries in layer: %1.</source>
        <translation>レイヤ %1 の無効なジオメトリの修正が完了しました。</translation>
    </message>
</context>
<context>
    <name>BuildingDataAssigner</name>
    <message>
        <location filename="../algorithms/utils/building_data_assigner.py" line="175"/>
        <source>The field %1 does not exist.</source>
        <translation>フィールド %1 が存在しません。</translation>
    </message>
    <message>
        <location filename="../algorithms/utils/building_data_assigner.py" line="366"/>
        <source>Plugin</source>
        <translation>プラグイン</translation>
    </message>
    <message>
        <location filename="../algorithms/utils/building_data_assigner.py" line="215"/>
        <source>Completed attaching population to buildings.</source>
        <translation>建物への人口の付与が完了しました。</translation>
    </message>
    <message>
        <location filename="../algorithms/utils/building_data_assigner.py" line="366"/>
        <source>An error occurred: %1</source>
        <translation>エラーが発生しました: %1</translation>
    </message>
    <message>
        <location filename="../algorithms/utils/building_data_assigner.py" line="302"/>
        <source>No vacant house points were found for the year %1.</source>
        <translation>%1 年度に対応する空き家ポイントが見つかりませんでした。</translation>
    </message>
    <message>
        <location filename="../algorithms/utils/building_data_assigner.py" line="357"/>
        <source>Completed setting vacant house flags.</source>
        <translation>空き家フラグの設定が完了しました。</translation>
    </message>
</context>
<context>
    <name>ControlDock</name>
    <message>
        <location filename="../functions/visualization.py" line="266"/>
        <source>Data Catalog</source>
        <translation>データカタログ</translation>
    </message>
    <message>
        <location filename="../functions/visualization.py" line="294"/>
        <source>Select Visualization Data</source>
        <translation>可視化データ選択</translation>
    </message>
    <message>
        <location filename="../functions/visualization.py" line="304"/>
        <source>Select Year</source>
        <translation>年次選択</translation>
    </message>
    <message>
        <location filename="../functions/visualization.py" line="309"/>
        <source>Execute</source>
        <translation>実行</translation>
    </message>
    <message>
        <location filename="../functions/visualization.py" line="300"/>
        <source>Select Sub Item</source>
        <translation>評価指標選択</translation>
    </message>
    <message>
        <location filename="../functions/visualization.py" line="325"/>
        <source>Execute_sub</source>
        <translation>参考グラフ表示</translation>
    </message>
    <message>
        <location filename="../functions/visualization.py" line="320"/>
        <source>Select Sub Graph Data</source>
        <translation>参考評価指標選択</translation>
    </message>
</context>
<context>
    <name>CreateDirectory</name>
    <message>
        <location filename="../functions/create_directory.py" line="85"/>
        <source>Creating directory structure</source>
        <translation>フォルダ構成の作成</translation>
    </message>
    <message>
        <location filename="../functions/create_directory.py" line="97"/>
        <source>Open</source>
        <translation>フォルダを開く</translation>
    </message>
    <message>
        <location filename="../functions/create_directory.py" line="104"/>
        <source>Cancel</source>
        <translation>キャンセル</translation>
    </message>
    <message>
        <location filename="../functions/create_directory.py" line="132"/>
        <source>Select Directory</source>
        <translation>フォルダを選択</translation>
    </message>
    <message>
        <location filename="../functions/create_directory.py" line="144"/>
        <source>The specified folder does not exist.</source>
        <translation>フォルダが存在しません</translation>
    </message>
    <message>
        <location filename="../functions/create_directory.py" line="154"/>
        <source>Directory creation completed:</source>
        <translation>フォルダを作成しました:</translation>
    </message>
    <message>
        <location filename="../functions/create_directory.py" line="164"/>
        <source>Failed to create directory: {e}</source>
        <translation>フォルダの作成に失敗しました</translation>
    </message>
    <message>
        <location filename="../functions/create_directory.py" line="166"/>
        <source>Path could not be found.</source>
        <translation>フォルダパスが指定されていません</translation>
    </message>
    <message>
        <location filename="../functions/create_directory.py" line="157"/>
        <source>completed</source>
        <translation>完了</translation>
    </message>
    <message>
        <location filename="../functions/create_directory.py" line="177"/>
        <source>Configuration file not found. Using default values.</source>
        <translation>設定ファイルが見つかりません。デフォルト値を使用します。</translation>
    </message>
    <message>
        <location filename="../functions/create_directory.py" line="181"/>
        <source>XML parsing error. Using default values.</source>
        <translation>XMLファイルの解析エラーです。デフォルト値を使用します。</translation>
    </message>
</context>
<context>
    <name>DataLoader</name>
    <message>
        <location filename="../algorithms/utils/data_loader.py" line="46"/>
        <source>buildings layer</source>
        <translation>建物レイヤ</translation>
    </message>
    <message>
        <location filename="../algorithms/utils/data_loader.py" line="47"/>
        <source>The %1 was not found.</source>
        <translation>%1 が見つかりませんでした。</translation>
    </message>
    <message>
        <location filename="../algorithms/utils/data_loader.py" line="64"/>
        <source>Failed to join layers.</source>
        <translation>レイヤの結合に失敗しました。</translation>
    </message>
    <message>
        <location filename="../algorithms/utils/data_loader.py" line="99"/>
        <source>Failed to add layer to GeoPackage.</source>
        <translation>レイヤをGeoPackageに追加することに失敗しました。</translation>
    </message>
    <message>
        <location filename="../algorithms/utils/data_loader.py" line="114"/>
        <source>An error occurred: %1</source>
        <translation>エラーが発生しました: %1</translation>
    </message>
    <message>
        <location filename="../algorithms/utils/data_loader.py" line="286"/>
        <source>Plugin</source>
        <translation>プラグイン</translation>
    </message>
    <message>
        <location filename="../algorithms/utils/data_loader.py" line="119"/>
        <source>Failed to load data.</source>
        <translation>データの読み込みに失敗しました。</translation>
    </message>
    <message>
        <location filename="../algorithms/utils/data_loader.py" line="214"/>
        <source>Failed to bulk update features.</source>
        <translation>フィーチャの一括更新に失敗しました。</translation>
    </message>
    <message>
        <location filename="../algorithms/utils/data_loader.py" line="271"/>
        <source>Fixing invalid geometries in layer: %1.</source>
        <translation>レイヤ %1 の無効なジオメトリを修正しています。</translation>
    </message>
    <message>
        <location filename="../algorithms/utils/data_loader.py" line="283"/>
        <source>Completed fixing invalid geometries in layer: %1.</source>
        <translation>レイヤ %1 の無効なジオメトリの修正が完了しました。</translation>
    </message>
</context>
<context>
    <name>DirMaker</name>
    <message>
        <location filename="../algorithms/utils/dir_maker.py" line="71"/>
        <source>Created folder structure at %1.</source>
        <translation>%1 にフォルダ構成を作成しました。</translation>
    </message>
    <message>
        <location filename="../algorithms/utils/dir_maker.py" line="82"/>
        <source>Plugin</source>
        <translation>プラグイン</translation>
    </message>
    <message>
        <location filename="../algorithms/utils/dir_maker.py" line="82"/>
        <source>An error occurred: %1</source>
        <translation>エラーが発生しました: %1</translation>
    </message>
</context>
<context>
    <name>DisasterPreventionMetricCalculator</name>
    <message>
        <location filename="../algorithms/utils/disaster_prevention_metric_calculator.py" line="101"/>
        <source>The %1 layer was not found.</source>
        <translation>%1 レイヤが見つかりませんでした。</translation>
    </message>
    <message>
        <location filename="../algorithms/utils/disaster_prevention_metric_calculator.py" line="415"/>
        <source>Failed to add layer to GeoPackage.</source>
        <translation>レイヤをGeoPackageに追加することに失敗しました。</translation>
    </message>
    <message>
        <location filename="../algorithms/utils/disaster_prevention_metric_calculator.py" line="674"/>
        <source>An error occurred: %1</source>
        <translation>エラーが発生しました: %1</translation>
    </message>
    <message>
        <location filename="../algorithms/utils/disaster_prevention_metric_calculator.py" line="714"/>
        <source>Plugin</source>
        <translation>プラグイン</translation>
    </message>
    <message>
        <location filename="../algorithms/utils/disaster_prevention_metric_calculator.py" line="685"/>
        <source>The data to export is empty.</source>
        <translation>エクスポートするデータが空です。</translation>
    </message>
    <message>
        <location filename="../algorithms/utils/disaster_prevention_metric_calculator.py" line="700"/>
        <source>File export completed: %1.</source>
        <translation>ファイルのエクスポートが完了しました: %1。</translation>
    </message>
    <message>
        <location filename="../algorithms/utils/disaster_prevention_metric_calculator.py" line="711"/>
        <source>An error occurred during file export: %1.</source>
        <translation>ファイルエクスポート中にエラーが発生しました: %1。</translation>
    </message>
</context>
<context>
    <name>FacilityDataGenerator</name>
    <message>
        <location filename="../algorithms/utils/facility_data_generator.py" line="69"/>
        <source>The Shapefile for %1 was not found.</source>
        <translation>%1 のShapefileが見つかりませんでした。</translation>
    </message>
    <message>
        <location filename="../algorithms/utils/facility_data_generator.py" line="324"/>
        <source>Plugin</source>
        <translation>プラグイン</translation>
    </message>
    <message>
        <location filename="../algorithms/utils/facility_data_generator.py" line="95"/>
        <source>Failed to load layer: %1</source>
        <translation>レイヤ %1 の読み込みに失敗しました。</translation>
    </message>
    <message>
        <location filename="../algorithms/utils/facility_data_generator.py" line="115"/>
        <source>Failed to add layer to GeoPackage.</source>
        <translation>レイヤをGeoPackageに追加することに失敗しました。</translation>
    </message>
    <message>
        <location filename="../algorithms/utils/facility_data_generator.py" line="117"/>
        <source>facility</source>
        <translation>都市施設</translation>
    </message>
    <message>
        <location filename="../algorithms/utils/facility_data_generator.py" line="118"/>
        <source>%1 data generation completed.</source>
        <translation>%1 のデータ生成が完了しました。</translation>
    </message>
    <message>
        <location filename="../algorithms/utils/facility_data_generator.py" line="128"/>
        <source>An error occurred: %1</source>
        <translation>エラーが発生しました: %1</translation>
    </message>
    <message>
        <location filename="../algorithms/utils/facility_data_generator.py" line="137"/>
        <source>Directory: %1</source>
        <translation>ディレクトリ: %1</translation>
    </message>
    <message>
        <location filename="../algorithms/utils/facility_data_generator.py" line="158"/>
        <source>Failed to extract year from file path: %1</source>
        <translation>ファイルパス %1 から年度を抽出できませんでした。</translation>
    </message>
    <message>
        <location filename="../algorithms/utils/facility_data_generator.py" line="168"/>
        <source>An error occurred during year extraction: %1</source>
        <translation>年度抽出中にエラーが発生しました: %1</translation>
    </message>
    <message>
        <location filename="../algorithms/utils/facility_data_generator.py" line="234"/>
        <source>Skipped feature %1. Unknown type: %2.</source>
        <translation>フィーチャ %1 をスキップしました。不明なタイプ: %2。</translation>
    </message>
    <message>
        <location filename="../algorithms/utils/facility_data_generator.py" line="309"/>
        <source>%1 was detected. Using SHIFT_JIS for the file %2.</source>
        <translation>%1 が検出されました。ファイル %2 に対してSHIFT_JISを使用します。</translation>
    </message>
    <message>
        <location filename="../algorithms/utils/facility_data_generator.py" line="320"/>
        <source>No corresponding DBF file was found for the specified path: %1.</source>
        <translation>指定されたパス %1 に対応するDBFファイルが見つかりませんでした。</translation>
    </message>
</context>
<context>
    <name>FinancialDataGenerator</name>
    <message>
        <location filename="../algorithms/utils/financial_data_generator.py" line="61"/>
        <source>Failed to load layer: %1</source>
        <translation>レイヤ %1 の読み込みに失敗しました。</translation>
    </message>
    <message>
        <location filename="../algorithms/utils/financial_data_generator.py" line="429"/>
        <source>Plugin</source>
        <translation>プラグイン</translation>
    </message>
    <message>
        <location filename="../algorithms/utils/financial_data_generator.py" line="84"/>
        <source>The year field was not found in %1.</source>
        <translation>%1 に年度フィールドが見つかりませんでした。</translation>
    </message>
    <message>
        <location filename="../algorithms/utils/financial_data_generator.py" line="217"/>
        <source>land price</source>
        <translation>公示地価</translation>
    </message>
    <message>
        <location filename="../algorithms/utils/financial_data_generator.py" line="165"/>
        <source>No valid %1 Shapefile was found.</source>
        <translation>有効な %1 Shapefileが見つかりませんでした。</translation>
    </message>
    <message>
        <location filename="../algorithms/utils/financial_data_generator.py" line="188"/>
        <source>The %1 layer was not found.</source>
        <translation>%1 レイヤが見つかりませんでした。</translation>
    </message>
    <message>
        <location filename="../algorithms/utils/financial_data_generator.py" line="213"/>
        <source>Failed to add layer to GeoPackage.</source>
        <translation>レイヤをGeoPackageに追加することに失敗しました。</translation>
    </message>
    <message>
        <location filename="../algorithms/utils/financial_data_generator.py" line="218"/>
        <source>%1 data generation completed.</source>
        <translation>%1 のデータ生成が完了しました。</translation>
    </message>
    <message>
        <location filename="../algorithms/utils/financial_data_generator.py" line="349"/>
        <source>An error occurred: %1</source>
        <translation>エラーが発生しました: %1</translation>
    </message>
    <message>
        <location filename="../algorithms/utils/financial_data_generator.py" line="242"/>
        <source>land price layer</source>
        <translation>公示地価レイヤ</translation>
    </message>
    <message>
        <location filename="../algorithms/utils/financial_data_generator.py" line="243"/>
        <source>The %1 layer does not contain year data.</source>
        <translation>%1 レイヤには年度データが含まれていません。</translation>
    </message>
    <message>
        <location filename="../algorithms/utils/financial_data_generator.py" line="334"/>
        <source>Added average land price and its changes to the mesh layer.</source>
        <translation>平均地価とその変化をメッシュレイヤに追加しました。</translation>
    </message>
    <message>
        <location filename="../algorithms/utils/financial_data_generator.py" line="371"/>
        <source>Directory: %1</source>
        <translation>ディレクトリ: %1</translation>
    </message>
    <message>
        <location filename="../algorithms/utils/financial_data_generator.py" line="407"/>
        <source>%1 was detected. Using SHIFT_JIS for the file %2.</source>
        <translation>%1 が検出されました。ファイル %2 に対してSHIFT_JISを使用します。</translation>
    </message>
    <message>
        <location filename="../algorithms/utils/financial_data_generator.py" line="417"/>
        <source>Detected encoding: %1</source>
        <translation>検出されたエンコーディング: %1</translation>
    </message>
    <message>
        <location filename="../algorithms/utils/financial_data_generator.py" line="425"/>
        <source>No corresponding DBF file was found for the specified path: %1.</source>
        <translation>指定されたパス %1 に対応するDBFファイルが見つかりませんでした。</translation>
    </message>
</context>
<context>
    <name>FiscalMetricCalculator</name>
    <message>
        <location filename="../algorithms/utils/fiscal_metric_calculator.py" line="54"/>
        <source>The %1 layer was not found.</source>
        <translation>%1 レイヤが見つかりませんでした。</translation>
    </message>
    <message>
        <location filename="../algorithms/utils/fiscal_metric_calculator.py" line="260"/>
        <source>An error occurred: %1</source>
        <translation>エラーが発生しました: %1</translation>
    </message>
    <message>
        <location filename="../algorithms/utils/fiscal_metric_calculator.py" line="300"/>
        <source>Plugin</source>
        <translation>プラグイン</translation>
    </message>
    <message>
        <location filename="../algorithms/utils/fiscal_metric_calculator.py" line="271"/>
        <source>The data to export is empty.</source>
        <translation>エクスポートするデータが空です。</translation>
    </message>
    <message>
        <location filename="../algorithms/utils/fiscal_metric_calculator.py" line="286"/>
        <source>File export completed: %1.</source>
        <translation>ファイルのエクスポートが完了しました: %1。</translation>
    </message>
    <message>
        <location filename="../algorithms/utils/fiscal_metric_calculator.py" line="297"/>
        <source>An error occurred during file export: %1.</source>
        <translation>ファイルエクスポート中にエラーが発生しました: %1。</translation>
    </message>
</context>
<context>
    <name>GpkgManager</name>
    <message>
        <location filename="../algorithms/utils/gpkg_manager.py" line="49"/>
        <source>GeoPackage Manager has been reset. New path: %1.</source>
        <translation>GeoPackageマネージャがリセットされました。新しいパス: %1。</translation>
    </message>
    <message>
        <location filename="../algorithms/utils/gpkg_manager.py" line="242"/>
        <source>Plugin</source>
        <translation>プラグイン</translation>
    </message>
    <message>
        <location filename="../algorithms/utils/gpkg_manager.py" line="83"/>
        <source>Failed to create GeoPackage: %1</source>
        <translation>GeoPackageの作成に失敗しました: %1。</translation>
    </message>
    <message>
        <location filename="../algorithms/utils/gpkg_manager.py" line="89"/>
        <source>GeoPackage initialization completed. Path: %1</source>
        <translation>GeoPackageの初期化が完了しました。パス: %1。</translation>
    </message>
    <message>
        <location filename="../algorithms/utils/gpkg_manager.py" line="99"/>
        <source>GeoPackage initialization error: %1</source>
        <translation>GeoPackageの初期化中にエラーが発生しました: %1。</translation>
    </message>
    <message>
        <location filename="../algorithms/utils/gpkg_manager.py" line="104"/>
        <source>Failed to create GeoPackage.</source>
        <translation>GeoPackageの作成に失敗しました。</translation>
    </message>
    <message>
        <location filename="../algorithms/utils/gpkg_manager.py" line="130"/>
        <source>GeoPackage layer %1 added to the layer panel.</source>
        <translation>GeoPackageレイヤ %1 をレイヤパネルに追加しました。</translation>
    </message>
    <message>
        <location filename="../algorithms/utils/gpkg_manager.py" line="137"/>
        <source>GeoPackage layer %1 loaded.</source>
        <translation>GeoPackageレイヤ %1 を読み込みました。</translation>
    </message>
    <message>
        <location filename="../algorithms/utils/gpkg_manager.py" line="147"/>
        <source>Error loading GeoPackage layer: %1</source>
        <translation>GeoPackageレイヤ %1 の読み込み中にエラーが発生しました。</translation>
    </message>
    <message>
        <location filename="../algorithms/utils/gpkg_manager.py" line="179"/>
        <source>Layer %1 added to GeoPackage %2.</source>
        <translation>レイヤ %1 がGeoPackage %2 に追加されました。</translation>
    </message>
    <message>
        <location filename="../algorithms/utils/gpkg_manager.py" line="190"/>
        <source>An error occurred: %1</source>
        <translation>エラーが発生しました: %1。</translation>
    </message>
    <message>
        <location filename="../algorithms/utils/gpkg_manager.py" line="211"/>
        <source>Failed to delete layer: %1</source>
        <translation>レイヤ %1 の削除に失敗しました。</translation>
    </message>
    <message>
        <location filename="../algorithms/utils/gpkg_manager.py" line="216"/>
        <source>Layer %1 deleted from GeoPackage %2.</source>
        <translation>レイヤ %1 がGeoPackage %2 から削除されました。</translation>
    </message>
    <message>
        <location filename="../algorithms/utils/gpkg_manager.py" line="227"/>
        <source>Error deleting GeoPackage layer: %1</source>
        <translation>GeoPackageレイヤ %1 の削除中にエラーが発生しました。</translation>
    </message>
    <message>
        <location filename="../algorithms/utils/gpkg_manager.py" line="242"/>
        <source>Failed to load GeoPackage: %1</source>
        <translation>GeoPackage %1 の読み込みに失敗しました。</translation>
    </message>
</context>
<context>
    <name>GraphDock</name>
    <message>
        <location filename="../functions/visualization.py" line="436"/>
        <source>Visualization Graph</source>
        <translation>グラフ</translation>
    </message>
    <message>
        <location filename="../functions/visualization.py" line="628"/>
        <source>No data available</source>
        <translation>データが見つかりません</translation>
    </message>
    <message>
        <location filename="../functions/visualization.py" line="438"/>
        <source>Comparison Graph</source>
        <translation>参考グラフ</translation>
    </message>
</context>
<context>
    <name>LandUseMetricCalculator</name>
    <message>
        <location filename="../algorithms/utils/land_use_metric_calculator.py" line="56"/>
        <source>The %1 layer was not found.</source>
        <translation>%1 レイヤが見つかりませんでした。</translation>
    </message>
    <message>
        <location filename="../algorithms/utils/land_use_metric_calculator.py" line="95"/>
        <source>Failed to add layer to GeoPackage.</source>
        <translation>レイヤをGeoPackageに追加するのに失敗しました。</translation>
    </message>
    <message>
        <location filename="../algorithms/utils/land_use_metric_calculator.py" line="342"/>
        <source>An error occurred: %1</source>
        <translation>エラーが発生しました: %1</translation>
    </message>
    <message>
        <location filename="../algorithms/utils/land_use_metric_calculator.py" line="382"/>
        <source>Plugin</source>
        <translation>プラグイン</translation>
    </message>
    <message>
        <location filename="../algorithms/utils/land_use_metric_calculator.py" line="353"/>
        <source>The data to export is empty.</source>
        <translation>エクスポートするデータが空です。</translation>
    </message>
    <message>
        <location filename="../algorithms/utils/land_use_metric_calculator.py" line="368"/>
        <source>File export completed: %1.</source>
        <translation>ファイルのエクスポートが完了しました: %1。</translation>
    </message>
    <message>
        <location filename="../algorithms/utils/land_use_metric_calculator.py" line="379"/>
        <source>An error occurred during file export: %1.</source>
        <translation>ファイルエクスポート中にエラーが発生しました: %1。</translation>
    </message>
</context>
<context>
    <name>MetricCalculation</name>
    <message>
        <location filename="../functions/metric_calculation.py" line="107"/>
        <source>Metric Calculation</source>
        <translation>評価指標算出</translation>
    </message>
    <message>
        <location filename="../functions/metric_calculation.py" line="237"/>
        <source>Input Data Folder</source>
        <translation>インプットデータ格納フォルダ</translation>
    </message>
    <message>
        <location filename="../functions/metric_calculation.py" line="239"/>
        <source>Output Data Folder</source>
        <translation>アウトプットデータ格納フォルダの指定</translation>
    </message>
    <message>
        <location filename="../functions/metric_calculation.py" line="241"/>
        <source>Threshold for Bus (m)</source>
        <translation>閾値設定(バス・m)</translation>
    </message>
    <message>
        <location filename="../functions/metric_calculation.py" line="243"/>
        <source>Threshold for Railway (m)</source>
        <translation>閾値設定(鉄道・m)</translation>
    </message>
    <message>
        <location filename="../functions/metric_calculation.py" line="245"/>
        <source>Threshold for Shelter (m)</source>
        <translation>閾値設定(避難施設・m)</translation>
    </message>
    <message>
        <location filename="../functions/metric_calculation.py" line="131"/>
        <source>OK</source>
        <translation></translation>
    </message>
    <message>
        <location filename="../functions/metric_calculation.py" line="277"/>
        <source>Cancel</source>
        <translation>キャンセル</translation>
    </message>
    <message>
        <location filename="../functions/metric_calculation.py" line="178"/>
        <source>Select Folder</source>
        <translation>フォルダを選択</translation>
    </message>
    <message>
        <location filename="../functions/metric_calculation.py" line="199"/>
        <source>Configuration file not found. Using default values.</source>
        <translation>設定ファイルが見つかりません。デフォルト値を使用します。</translation>
    </message>
    <message>
        <location filename="../functions/metric_calculation.py" line="203"/>
        <source>XML parsing error. Using default values.</source>
        <translation>XMLファイルの解析エラーです。デフォルト値を使用します。</translation>
    </message>
    <message>
        <location filename="../functions/metric_calculation.py" line="277"/>
        <source>Processing...</source>
        <translation>処理中です...</translation>
    </message>
    <message>
        <location filename="../functions/metric_calculation.py" line="248"/>
        <source>Missing Required Fields</source>
        <translation>必須フィールドが不足しています</translation>
    </message>
    <message>
        <location filename="../functions/metric_calculation.py" line="248"/>
        <source>%1</source>
        <translation>%1</translation>
    </message>
</context>
<context>
    <name>MetricCalculationWorker</name>
    <message>
        <location filename="../algorithms/workers/metric_calculation_worker.py" line="238"/>
        <source>Processing completed</source>
        <translation>処理が完了しました</translation>
    </message>
    <message>
        <location filename="../algorithms/workers/metric_calculation_worker.py" line="240"/>
        <source>Processing was canceled</source>
        <translation>処理がキャンセルされました</translation>
    </message>
    <message>
        <location filename="../algorithms/workers/metric_calculation_worker.py" line="243"/>
        <source>An error occurred: %1</source>
        <translation>エラーが発生しました: %1</translation>
    </message>
    <message>
        <location filename="../algorithms/workers/metric_calculation_worker.py" line="75"/>
        <source>%1 already exists in the layer panel</source>
        <translation>%1 はレイヤパネルに既に存在します</translation>
    </message>
    <message>
        <location filename="../algorithms/workers/metric_calculation_worker.py" line="84"/>
        <source>Unable to retrieve pipe for OSM layer</source>
        <translation>OSMレイヤのパイプを取得できません</translation>
    </message>
    <message>
        <location filename="../algorithms/workers/metric_calculation_worker.py" line="91"/>
        <source>Set OSM grayscale mode to GrayscaleLuminosity</source>
        <translation>OSMのグレースケールモードをGrayscaleLuminosityに設定しました</translation>
    </message>
    <message>
        <location filename="../algorithms/workers/metric_calculation_worker.py" line="95"/>
        <source>Hue/Saturation filter is not available for OSM layer</source>
        <translation>OSMレイヤにはHue/Saturationフィルターが使用できません</translation>
    </message>
    <message>
        <location filename="../algorithms/workers/metric_calculation_worker.py" line="102"/>
        <source>Added %1 to the layer panel</source>
        <translation>%1 をレイヤパネルに追加しました</translation>
    </message>
    <message>
        <location filename="../algorithms/workers/metric_calculation_worker.py" line="104"/>
        <source>Failed to add %1</source>
        <translation>%1 の追加に失敗しました</translation>
    </message>
</context>
<context>
    <name>Output</name>
    <message>
        <location filename="../functions/output.py" line="62"/>
        <source>Output</source>
        <translation>出力</translation>
    </message>
    <message>
        <location filename="../functions/output.py" line="99"/>
        <source>Output Folder:</source>
        <translation>出力先フォルダ:</translation>
    </message>
    <message>
        <location filename="../functions/output.py" line="135"/>
        <source>Select Output Folder</source>
        <translation>出力先フォルダを選択</translation>
    </message>
    <message>
        <location filename="../functions/output.py" line="164"/>
        <source>ERROR</source>
        <translation>エラー</translation>
    </message>
    <message>
        <location filename="../functions/output.py" line="164"/>
        <source>No CSV files were found in the selected folder:&lt;br&gt;%1</source>
        <translation>フォルダ内にCSVファイルが見つかりませんでした:&lt;br&gt;%1</translation>
    </message>
    <message>
        <location filename="../functions/output.py" line="173"/>
        <source>valuation index_%1.zip</source>
        <translation>評価指標_%1.zip</translation>
    </message>
    <message>
        <location filename="../functions/output.py" line="193"/>
        <source>Success</source>
        <translation>成功</translation>
    </message>
    <message>
        <location filename="../functions/output.py" line="193"/>
        <source>file generated successfully</source>
        <translation>出力に成功しました</translation>
    </message>
</context>
<context>
    <name>PlateauStatisticsVisualizationPlugin</name>
    <message>
        <location filename="../PlateauStatisticsVisualizationPlugin.py" line="220"/>
        <source>&amp;Plateau Statistics Visualization Plugin</source>
        <translation></translation>
    </message>
    <message>
        <location filename="../PlateauStatisticsVisualizationPlugin.py" line="190"/>
        <source>Plateau Statistics Visualization Plugin</source>
        <translation></translation>
    </message>
</context>
<context>
    <name>PlateauStatisticsVisualizationPluginDockWidgetBase</name>
    <message>
        <location filename="../PlateauStatisticsVisualizationPlugin_dockwidget_base.ui" line="14"/>
        <source>function</source>
        <translation>機能</translation>
    </message>
    <message>
        <location filename="../PlateauStatisticsVisualizationPlugin_dockwidget_base.ui" line="35"/>
        <source>Create Folder</source>
        <translation>フォルダ作成</translation>
    </message>
    <message>
        <location filename="../PlateauStatisticsVisualizationPlugin_dockwidget_base.ui" line="54"/>
        <source>Metric Calculation</source>
        <translation>評価指標算出機能</translation>
    </message>
    <message>
        <location filename="../PlateauStatisticsVisualizationPlugin_dockwidget_base.ui" line="73"/>
        <source>Visualization</source>
        <translation>可視化機能</translation>
    </message>
    <message>
        <location filename="../PlateauStatisticsVisualizationPlugin_dockwidget_base.ui" line="92"/>
        <source>Output</source>
        <translation>データ出力</translation>
    </message>
</context>
<context>
    <name>PopulationDataGenerator</name>
    <message>
        <location filename="../algorithms/utils/population_data_generator.py" line="113"/>
        <source>%1 was not found.</source>
        <translation>%1 が見つかりませんでした。</translation>
    </message>
    <message>
        <location filename="../algorithms/utils/population_data_generator.py" line="434"/>
        <source>Failed to add layer to GeoPackage.</source>
        <translation>レイヤをGeoPackageに追加するのに失敗しました。</translation>
    </message>
    <message>
        <location filename="../algorithms/utils/population_data_generator.py" line="173"/>
        <source>meshes</source>
        <translation>メッシュ</translation>
    </message>
    <message>
        <location filename="../algorithms/utils/population_data_generator.py" line="437"/>
        <source>%1 data generation completed.</source>
        <translation>%1 のデータ生成が完了しました。</translation>
    </message>
    <message>
        <location filename="../algorithms/utils/population_data_generator.py" line="837"/>
        <source>Plugin</source>
        <translation>プラグイン</translation>
    </message>
    <message>
        <location filename="../algorithms/utils/population_data_generator.py" line="837"/>
        <source>An error occurred: %1</source>
        <translation>エラーが発生しました: %1</translation>
    </message>
    <message>
        <location filename="../algorithms/utils/population_data_generator.py" line="233"/>
        <source>Population data creation for year: %1</source>
        <translation>%1 年度の人口データ作成</translation>
    </message>
    <message>
        <location filename="../algorithms/utils/population_data_generator.py" line="271"/>
        <source>Population data creation - Detected encoding: %1 for file: %2</source>
        <translation>人口データ作成 - 検出されたエンコーディング: %1 ファイル: %2</translation>
    </message>
    <message>
        <location filename="../algorithms/utils/population_data_generator.py" line="260"/>
        <source>Encoding detection error for file: %1. Attempting to detect using an alternative method.</source>
        <translation>ファイル %1 のエンコーディング検出エラー。別の方法で検出を試みます。</translation>
    </message>
    <message>
        <location filename="../algorithms/utils/population_data_generator.py" line="436"/>
        <source>future population</source>
        <translation>将来人口</translation>
    </message>
    <message>
        <location filename="../algorithms/utils/population_data_generator.py" line="407"/>
        <source>The Shapefile for %1 was not found.</source>
        <translation>%1 のShapefileが見つかりませんでした。</translation>
    </message>
    <message>
        <location filename="../algorithms/utils/population_data_generator.py" line="677"/>
        <source>Adding future estimated population data has been completed.</source>
        <translation>将来推定人口データの追加が完了しました。</translation>
    </message>
</context>
<context>
    <name>PublicTransportMetricCalculator</name>
    <message>
        <location filename="../algorithms/utils/public_transport_metric_calculator.py" line="81"/>
        <source>The %1 layer was not found.</source>
        <translation>%1 レイヤが見つかりませんでした。</translation>
    </message>
    <message>
        <location filename="../algorithms/utils/public_transport_metric_calculator.py" line="120"/>
        <source>Failed to add layer to GeoPackage.</source>
        <translation>レイヤをGeoPackageに追加するのに失敗しました。</translation>
    </message>
    <message>
        <location filename="../algorithms/utils/public_transport_metric_calculator.py" line="954"/>
        <source>An error occurred: %1</source>
        <translation>エラーが発生しました: %1</translation>
    </message>
    <message>
        <location filename="../algorithms/utils/public_transport_metric_calculator.py" line="994"/>
        <source>Plugin</source>
        <translation>プラグイン</translation>
    </message>
    <message>
        <location filename="../algorithms/utils/public_transport_metric_calculator.py" line="965"/>
        <source>The data to export is empty.</source>
        <translation>エクスポートするデータが空です。</translation>
    </message>
    <message>
        <location filename="../algorithms/utils/public_transport_metric_calculator.py" line="980"/>
        <source>File export completed: %1.</source>
        <translation>ファイルのエクスポートが完了しました: %1。</translation>
    </message>
    <message>
        <location filename="../algorithms/utils/public_transport_metric_calculator.py" line="991"/>
        <source>An error occurred during file export: %1.</source>
        <translation>ファイルエクスポート中にエラーが発生しました: %1。</translation>
    </message>
</context>
<context>
    <name>ResidentialInductionMetricCalculator</name>
    <message>
        <location filename="../algorithms/utils/residential_induction_metric_calculator.py" line="61"/>
        <source>The %1 layer was not found.</source>
        <translation>%1 レイヤが見つかりませんでした。</translation>
    </message>
    <message>
        <location filename="../algorithms/utils/residential_induction_metric_calculator.py" line="73"/>
        <source>Comparative future year: %1, Target population: %2</source>
        <translation>比較将来年度: %1, 目標人口: %2</translation>
    </message>
    <message>
        <location filename="../algorithms/utils/residential_induction_metric_calculator.py" line="703"/>
        <source>Plugin</source>
        <translation>プラグイン</translation>
    </message>
    <message>
        <location filename="../algorithms/utils/residential_induction_metric_calculator.py" line="84"/>
        <source>Target population data was not found.</source>
        <translation>目標人口データが見つかりませんでした。</translation>
    </message>
    <message>
        <location filename="../algorithms/utils/residential_induction_metric_calculator.py" line="127"/>
        <source>Failed to add layer to GeoPackage.</source>
        <translation>レイヤをGeoPackageに追加するのに失敗しました。</translation>
    </message>
    <message>
        <location filename="../algorithms/utils/residential_induction_metric_calculator.py" line="663"/>
        <source>An error occurred: %1</source>
        <translation>エラーが発生しました: %1</translation>
    </message>
    <message>
        <location filename="../algorithms/utils/residential_induction_metric_calculator.py" line="674"/>
        <source>The data to export is empty.</source>
        <translation>エクスポートするデータが空です。</translation>
    </message>
    <message>
        <location filename="../algorithms/utils/residential_induction_metric_calculator.py" line="689"/>
        <source>File export completed: %1.</source>
        <translation>ファイルのエクスポートが完了しました: %1。</translation>
    </message>
    <message>
        <location filename="../algorithms/utils/residential_induction_metric_calculator.py" line="700"/>
        <source>An error occurred during file export: %1.</source>
        <translation>ファイルエクスポート中にエラーが発生しました: %1。</translation>
    </message>
</context>
<context>
    <name>TransportationDataGenerator</name>
    <message>
        <location filename="../algorithms/utils/transportation_data_generator.py" line="829"/>
        <source>An error occurred: %1</source>
        <translation>エラーが発生しました: %1</translation>
    </message>
    <message>
        <location filename="../algorithms/utils/transportation_data_generator.py" line="929"/>
        <source>Plugin</source>
        <translation>プラグイン</translation>
    </message>
    <message>
        <location filename="../algorithms/utils/transportation_data_generator.py" line="114"/>
        <source>Shapefile to be imported: %1</source>
        <translation>インポートするShapefile: %1</translation>
    </message>
    <message>
        <location filename="../algorithms/utils/transportation_data_generator.py" line="164"/>
        <source>road network</source>
        <translation>道路ネットワーク</translation>
    </message>
    <message>
        <location filename="../algorithms/utils/transportation_data_generator.py" line="396"/>
        <source>%1 cannot be loaded as %2 data.</source>
        <translation>%1 を %2 データとして読み込むことができません。</translation>
    </message>
    <message>
        <location filename="../algorithms/utils/transportation_data_generator.py" line="460"/>
        <source>Failed to add layer to GeoPackage.</source>
        <translation>レイヤをGeoPackageに追加するのに失敗しました。</translation>
    </message>
    <message>
        <location filename="../algorithms/utils/transportation_data_generator.py" line="818"/>
        <source>%1 data generation completed.</source>
        <translation>%1 のデータ生成が完了しました。</translation>
    </message>
    <message>
        <location filename="../algorithms/utils/transportation_data_generator.py" line="319"/>
        <source>railway station</source>
        <translation>鉄道駅</translation>
    </message>
    <message>
        <location filename="../algorithms/utils/transportation_data_generator.py" line="349"/>
        <source>The Shapefile for %1 was not found.</source>
        <translation>%1 のShapefileが見つかりませんでした。</translation>
    </message>
    <message>
        <location filename="../algorithms/utils/transportation_data_generator.py" line="787"/>
        <source>Failed to load layer: %1</source>
        <translation>レイヤ %1 の読み込みに失敗しました。</translation>
    </message>
    <message>
        <location filename="../algorithms/utils/transportation_data_generator.py" line="462"/>
        <source>railway network</source>
        <translation>鉄道ネットワーク</translation>
    </message>
    <message>
        <location filename="../algorithms/utils/transportation_data_generator.py" line="495"/>
        <source>GTFS folder for the bus network</source>
        <translation>バスネットワークのGTFSフォルダ</translation>
    </message>
    <message>
        <location filename="../algorithms/utils/transportation_data_generator.py" line="496"/>
        <source>The %1 was not found.</source>
        <translation>%1 が見つかりませんでした。</translation>
    </message>
    <message>
        <location filename="../algorithms/utils/transportation_data_generator.py" line="543"/>
        <source>Processing GTFS folder: %1</source>
        <translation>GTFSフォルダを処理中: %1</translation>
    </message>
    <message>
        <location filename="../algorithms/utils/transportation_data_generator.py" line="693"/>
        <source>bus network</source>
        <translation>バスネットワーク</translation>
    </message>
    <message>
        <location filename="../algorithms/utils/transportation_data_generator.py" line="720"/>
        <source>The %1 layer was not found.</source>
        <translation>%1 レイヤが見つかりませんでした。</translation>
    </message>
    <message>
        <location filename="../algorithms/utils/transportation_data_generator.py" line="817"/>
        <source>traffic</source>
        <translation>発生集中量</translation>
    </message>
    <message>
        <location filename="../algorithms/utils/transportation_data_generator.py" line="838"/>
        <source>Directory: %1</source>
        <translation>ディレクトリ: %1</translation>
    </message>
    <message>
        <location filename="../algorithms/utils/transportation_data_generator.py" line="872"/>
        <source>Failed to extract year from file path: %1</source>
        <translation>ファイルパス %1 から年度を抽出するのに失敗しました。</translation>
    </message>
    <message>
        <location filename="../algorithms/utils/transportation_data_generator.py" line="882"/>
        <source>An error occurred during year extraction: %1</source>
        <translation>年度抽出中にエラーが発生しました: %1</translation>
    </message>
    <message>
        <location filename="../algorithms/utils/transportation_data_generator.py" line="904"/>
        <source>No corresponding DBF file was found for the specified path: %1.</source>
        <translation>指定されたパス %1 に対応するDBFファイルが見つかりませんでした。</translation>
    </message>
    <message>
        <location filename="../algorithms/utils/transportation_data_generator.py" line="928"/>
        <source>Failed to load CSV file: %1</source>
        <translation>CSVファイル %1 の読み込みに失敗しました。</translation>
    </message>
</context>
<context>
    <name>UrbanFunctionInductionMetricCalculator</name>
    <message>
        <location filename="../algorithms/utils/urban_functionInduction_metric_calculator.py" line="64"/>
        <source>The %1 layer was not found.</source>
        <translation>%1 レイヤが見つかりませんでした。</translation>
    </message>
    <message>
        <location filename="../algorithms/utils/urban_functionInduction_metric_calculator.py" line="103"/>
        <source>Failed to add layer to GeoPackage.</source>
        <translation>レイヤをGeoPackageに追加するのに失敗しました。</translation>
    </message>
    <message>
        <location filename="../algorithms/utils/urban_functionInduction_metric_calculator.py" line="605"/>
        <source>An error occurred: %1</source>
        <translation>エラーが発生しました: %1</translation>
    </message>
    <message>
        <location filename="../algorithms/utils/urban_functionInduction_metric_calculator.py" line="645"/>
        <source>Plugin</source>
        <translation>プラグイン</translation>
    </message>
    <message>
        <location filename="../algorithms/utils/urban_functionInduction_metric_calculator.py" line="616"/>
        <source>The data to export is empty.</source>
        <translation>エクスポートするデータが空です。</translation>
    </message>
    <message>
        <location filename="../algorithms/utils/urban_functionInduction_metric_calculator.py" line="631"/>
        <source>File export completed: %1.</source>
        <translation>ファイルのエクスポートが完了しました: %1。</translation>
    </message>
    <message>
        <location filename="../algorithms/utils/urban_functionInduction_metric_calculator.py" line="642"/>
        <source>An error occurred during file export: %1.</source>
        <translation>ファイルエクスポート中にエラーが発生しました: %1。</translation>
    </message>
</context>
<context>
    <name>VacancyDataGenerator</name>
    <message>
        <location filename="../algorithms/utils/vacancy_data_generator.py" line="119"/>
        <source>Failed to load layer: %1</source>
        <translation>レイヤ %1 の読み込みに失敗しました。</translation>
    </message>
    <message>
        <location filename="../algorithms/utils/vacancy_data_generator.py" line="235"/>
        <source>Plugin</source>
        <translation>プラグイン</translation>
    </message>
    <message>
        <location filename="../algorithms/utils/vacancy_data_generator.py" line="156"/>
        <source>vacancy</source>
        <translation>空き家</translation>
    </message>
    <message>
        <location filename="../algorithms/utils/vacancy_data_generator.py" line="81"/>
        <source>The Shapefile for %1 was not found.</source>
        <translation>%1 のShapefileが見つかりませんでした。</translation>
    </message>
    <message>
        <location filename="../algorithms/utils/vacancy_data_generator.py" line="154"/>
        <source>Failed to add layer to GeoPackage.</source>
        <translation>レイヤをGeoPackageに追加するのに失敗しました。</translation>
    </message>
    <message>
        <location filename="../algorithms/utils/vacancy_data_generator.py" line="157"/>
        <source>%1 data generation completed.</source>
        <translation>%1 のデータ生成が完了しました。</translation>
    </message>
    <message>
        <location filename="../algorithms/utils/vacancy_data_generator.py" line="168"/>
        <source>An error occurred: %1</source>
        <translation>エラーが発生しました: %1</translation>
    </message>
    <message>
        <location filename="../algorithms/utils/vacancy_data_generator.py" line="177"/>
        <source>Directory: %1</source>
        <translation>ディレクトリ: %1</translation>
    </message>
    <message>
        <location filename="../algorithms/utils/vacancy_data_generator.py" line="213"/>
        <source>%1 was detected. Using SHIFT_JIS for the file %2.</source>
        <translation>%1 が検出されました。ファイル %2 に対して SHIFT_JIS を使用します。</translation>
    </message>
    <message>
        <location filename="../algorithms/utils/vacancy_data_generator.py" line="223"/>
        <source>Detected encoding: %1</source>
        <translation>検出されたエンコーディング: %1</translation>
    </message>
    <message>
        <location filename="../algorithms/utils/vacancy_data_generator.py" line="231"/>
        <source>No corresponding DBF file was found for the specified path: %1.</source>
        <translation>指定されたパス %1 に対応するDBFファイルが見つかりませんでした。</translation>
    </message>
</context>
<context>
    <name>ZoneDataGenerator</name>
    <message>
        <location filename="../algorithms/utils/zone_data_generator.py" line="61"/>
        <source>Failed to load layer: %1</source>
        <translation>レイヤ %1 の読み込みに失敗しました。</translation>
    </message>
    <message>
        <location filename="../algorithms/utils/zone_data_generator.py" line="252"/>
        <source>Plugin</source>
        <translation>プラグイン</translation>
    </message>
    <message>
        <location filename="../algorithms/utils/zone_data_generator.py" line="136"/>
        <source>zone</source>
        <translation>行政区域</translation>
    </message>
    <message>
        <location filename="../algorithms/utils/zone_data_generator.py" line="112"/>
        <source>No valid %1 Shapefile was found.</source>
        <translation>有効な %1 のShapefileが見つかりませんでした。</translation>
    </message>
    <message>
        <location filename="../algorithms/utils/zone_data_generator.py" line="134"/>
        <source>Failed to add layer to GeoPackage.</source>
        <translation>レイヤをGeoPackageに追加するのに失敗しました。</translation>
    </message>
    <message>
        <location filename="../algorithms/utils/zone_data_generator.py" line="137"/>
        <source>%1 data generation completed.</source>
        <translation>%1 のデータ生成が完了しました。</translation>
    </message>
    <message>
        <location filename="../algorithms/utils/zone_data_generator.py" line="148"/>
        <source>An error occurred: %1</source>
        <translation>エラーが発生しました: %1</translation>
    </message>
    <message>
        <location filename="../algorithms/utils/zone_data_generator.py" line="170"/>
        <source>Directory: %1</source>
        <translation>ディレクトリ: %1</translation>
    </message>
    <message>
        <location filename="../algorithms/utils/zone_data_generator.py" line="206"/>
        <source>%1 was detected. Using SHIFT_JIS for the file %2.</source>
        <translation>%1 が検出されました。ファイル %2 に対して SHIFT_JIS を使用します。</translation>
    </message>
    <message>
        <location filename="../algorithms/utils/zone_data_generator.py" line="216"/>
        <source>Detected encoding: %1</source>
        <translation>検出されたエンコーディング: %1</translation>
    </message>
    <message>
        <location filename="../algorithms/utils/zone_data_generator.py" line="224"/>
        <source>No corresponding DBF file was found for the specified path: %1.</source>
        <translation>指定されたパス %1 に対応するDBFファイルが見つかりませんでした。</translation>
    </message>
    <message>
        <location filename="../algorithms/utils/zone_data_generator.py" line="237"/>
        <source>Fixing invalid geometries in layer: %1.</source>
        <translation>レイヤ %1 の無効なジオメトリを修正中です。</translation>
    </message>
    <message>
        <location filename="../algorithms/utils/zone_data_generator.py" line="249"/>
        <source>Completed fixing invalid geometries in layer: %1.</source>
        <translation>レイヤ %1 の無効なジオメトリの修正が完了しました。</translation>
    </message>
</context>
</TS>
